<?xml version="1.0" encoding="UTF-8"?>
<!-- Generated by org.testng.reporters.JUnitReportReporter -->
<testsuite hostname="user" failures="0" tests="2" name="Sample.Sample2_Test" time="125.439" errors="2" timestamp="2021-05-12T22:13:45 IST" skipped="0">
  <testcase classname="Sample.Sample2_Test" name="signInToSkillRayApp" time="50.847">
    <error message="Method Sample.Sample2_Test.signInToSkillRayApp() didn&#039;t finish within the time-out 5000" type="org.testng.internal.thread.ThreadTimeoutException">
      <![CDATA[org.testng.internal.thread.ThreadTimeoutException: Method Sample.Sample2_Test.signInToSkillRayApp() didn't finish within the time-out 5000
at org.testng.internal.MethodInvocationHelper.invokeWithTimeoutWithNoExecutor(MethodInvocationHelper.java:322)
at org.testng.internal.MethodInvocationHelper.invokeWithTimeout(MethodInvocationHelper.java:280)
at org.testng.internal.TestInvoker.invokeMethod(TestInvoker.java:605)
at org.testng.internal.TestInvoker.invokeTestMethod(TestInvoker.java:174)
at org.testng.internal.TestMethodWithDataProviderMethodWorker.call(TestMethodWithDataProviderMethodWorker.java:77)
at org.testng.internal.TestMethodWithDataProviderMethodWorker.call(TestMethodWithDataProviderMethodWorker.java:15)
at java.base/java.util.concurrent.FutureTask.run(FutureTask.java:264)
at java.base/java.util.concurrent.Executors$RunnableAdapter.call(Executors.java:515)
at java.base/java.util.concurrent.FutureTask.run(FutureTask.java:264)
at java.base/java.util.concurrent.ThreadPoolExecutor.runWorker(ThreadPoolExecutor.java:1130)
at java.base/java.util.concurrent.ThreadPoolExecutor$Worker.run(ThreadPoolExecutor.java:630)
at java.base/java.lang.Thread.run(Thread.java:832)
]]>
    </error>
  </testcase> <!-- signInToSkillRayApp -->
  <system-out/>
  <testcase classname="Sample.Sample2_Test" name="signInToSkillRayApp" time="74.592">
    <error message="Method Sample.Sample2_Test.signInToSkillRayApp() didn&#039;t finish within the time-out 5000" type="org.testng.internal.thread.ThreadTimeoutException">
      <![CDATA[org.testng.internal.thread.ThreadTimeoutException: Method Sample.Sample2_Test.signInToSkillRayApp() didn't finish within the time-out 5000
at org.testng.internal.MethodInvocationHelper.invokeWithTimeoutWithNoExecutor(MethodInvocationHelper.java:322)
at org.testng.internal.MethodInvocationHelper.invokeWithTimeout(MethodInvocationHelper.java:280)
at org.testng.internal.TestInvoker.invokeMethod(TestInvoker.java:605)
at org.testng.internal.TestInvoker.invokeTestMethod(TestInvoker.java:174)
at org.testng.internal.TestMethodWithDataProviderMethodWorker.call(TestMethodWithDataProviderMethodWorker.java:77)
at org.testng.internal.TestMethodWithDataProviderMethodWorker.call(TestMethodWithDataProviderMethodWorker.java:15)
at java.base/java.util.concurrent.FutureTask.run(FutureTask.java:264)
at java.base/java.util.concurrent.Executors$RunnableAdapter.call(Executors.java:515)
at java.base/java.util.concurrent.FutureTask.run(FutureTask.java:264)
at java.base/java.util.concurrent.ThreadPoolExecutor.runWorker(ThreadPoolExecutor.java:1130)
at java.base/java.util.concurrent.ThreadPoolExecutor$Worker.run(ThreadPoolExecutor.java:630)
at java.base/java.lang.Thread.run(Thread.java:832)
]]>
    </error>
  </testcase> <!-- signInToSkillRayApp -->
  <system-out/>
</testsuite> <!-- Sample.Sample2_Test -->
